<?xml version="1.0"?>

<robot xmlns:xacro="http://ros.org/wiki/xacro" name="wombot_wheel">

	<xacro:macro name="wombot_wheel" params="wheel_prefix wheel_radius wheel_length color *joint_pose">
		<link name="${wheel_prefix}_wheel_link">
			<inertial>
				<mass value="0.01" />
				<origin xyz="0 0 0" />
				<inertia  ixx="0.02467" ixy="0" ixz="0" iyy="0.04411" iyz="0" izz="0.02467" />
			</inertial>
			<visual>
				<origin xyz="0 0 0" rpy="${M_PI/2} 0 0" />
				<geometry>
					<cylinder length="${wheel_length}" radius="${wheel_radius}" />
				</geometry>
				<material name="${color}"/>
					<!-- <color rgba="0.1 0.1 0.1 1"/>
				</material> -->
			</visual>
			<collision>
				<origin xyz="0 0 0" rpy="${M_PI/2} 0 0" />
				<geometry>
					<cylinder length="${wheel_length}" radius="${wheel_radius}" />
				</geometry>
			</collision>
		</link>

		<joint name="${wheel_prefix}_wheel_joint" type="continuous">
			<parent link="base_link"/>
			<child link="${wheel_prefix}_wheel_link"/>
			<xacro:insert_block name="joint_pose"/>
			<axis xyz="0 1 0" rpy="0 0 0" />
		</joint>

	</xacro:macro>
</robot>
